[2025-04-01T14:52:26.415+0000] {local_task_job_runner.py:123} INFO - ::group::Pre task execution logs
[2025-04-01T14:52:26.630+0000] {taskinstance.py:2614} INFO - Dependencies all met for dep_context=non-requeueable deps ti=<TaskInstance: my_dag_name.create_table scheduled__2021-12-30T00:00:00+00:00 [queued]>
[2025-04-01T14:52:26.687+0000] {taskinstance.py:2614} INFO - Dependencies all met for dep_context=requeueable deps ti=<TaskInstance: my_dag_name.create_table scheduled__2021-12-30T00:00:00+00:00 [queued]>
[2025-04-01T14:52:26.687+0000] {taskinstance.py:2867} INFO - Starting attempt 1 of 1
[2025-04-01T14:52:26.794+0000] {taskinstance.py:2890} INFO - Executing <Task(BigQueryCreateTableOperator): create_table> on 2021-12-30 00:00:00+00:00
[2025-04-01T14:52:26.894+0000] {warnings.py:112} WARNING - /home/***/.local/lib/python3.12/site-packages/***/task/task_runner/standard_task_runner.py:70: DeprecationWarning: This process (pid=3346) is multi-threaded, use of fork() may lead to deadlocks in the child.
  pid = os.fork()

[2025-04-01T14:52:26.905+0000] {standard_task_runner.py:72} INFO - Started process 3398 to run task
[2025-04-01T14:52:26.898+0000] {standard_task_runner.py:104} INFO - Running: ['***', 'tasks', 'run', 'my_dag_name', 'create_table', 'scheduled__2021-12-30T00:00:00+00:00', '--job-id', '751', '--raw', '--subdir', 'DAGS_FOLDER/con.py', '--cfg-path', '/tmp/tmpteobmhcx']
[2025-04-01T14:52:26.913+0000] {standard_task_runner.py:105} INFO - Job 751: Subtask create_table
[2025-04-01T14:52:27.126+0000] {task_command.py:467} INFO - Running <TaskInstance: my_dag_name.create_table scheduled__2021-12-30T00:00:00+00:00 [running]> on host 900d630d7d5f
[2025-04-01T14:52:28.125+0000] {taskinstance.py:3134} INFO - Exporting env vars: AIRFLOW_CTX_DAG_OWNER='***' AIRFLOW_CTX_DAG_ID='my_dag_name' AIRFLOW_CTX_TASK_ID='create_table' AIRFLOW_CTX_EXECUTION_DATE='2021-12-30T00:00:00+00:00' AIRFLOW_CTX_TRY_NUMBER='1' AIRFLOW_CTX_DAG_RUN_ID='scheduled__2021-12-30T00:00:00+00:00'
[2025-04-01T14:52:28.139+0000] {logging_mixin.py:190} INFO - Task instance is in running state
[2025-04-01T14:52:28.142+0000] {logging_mixin.py:190} INFO -  Previous state of the Task instance: queued
[2025-04-01T14:52:28.143+0000] {logging_mixin.py:190} INFO - Current task name:create_table state:running start_date:2025-04-01 14:52:26.634934+00:00
[2025-04-01T14:52:28.149+0000] {logging_mixin.py:190} INFO - Dag name:my_dag_name and current dag run status:running
[2025-04-01T14:52:28.150+0000] {taskinstance.py:732} INFO - ::endgroup::
[2025-04-01T14:52:28.215+0000] {connection.py:277} WARNING - Connection schemes (type: google_cloud_platform) shall not contain '_' according to RFC3986.
[2025-04-01T14:52:28.300+0000] {base.py:84} INFO - Retrieving connection 'gcp_co'
[2025-04-01T14:52:28.305+0000] {bigquery.py:1274} INFO - Creating table...
[2025-04-01T14:52:29.010+0000] {taskinstance.py:3313} ERROR - Task failed with exception
Traceback (most recent call last):
  File "/home/airflow/.local/lib/python3.12/site-packages/airflow/models/taskinstance.py", line 768, in _execute_task
    result = _execute_callable(context=context, **execute_callable_kwargs)
             ^^^^^^^^^^^^^^^^^^^^^^^^^^^^^^^^^^^^^^^^^^^^^^^^^^^^^^^^^^^^^
  File "/home/airflow/.local/lib/python3.12/site-packages/airflow/models/taskinstance.py", line 734, in _execute_callable
    return ExecutionCallableRunner(
           ^^^^^^^^^^^^^^^^^^^^^^^^
  File "/home/airflow/.local/lib/python3.12/site-packages/airflow/utils/operator_helpers.py", line 252, in run
    return self.func(*args, **kwargs)
           ^^^^^^^^^^^^^^^^^^^^^^^^^^
  File "/home/airflow/.local/lib/python3.12/site-packages/airflow/models/baseoperator.py", line 424, in wrapper
    return func(self, *args, **kwargs)
           ^^^^^^^^^^^^^^^^^^^^^^^^^^^
  File "/home/airflow/.local/lib/python3.12/site-packages/airflow/providers/google/cloud/operators/bigquery.py", line 1275, in execute
    self._table = bq_hook.create_table(
                  ^^^^^^^^^^^^^^^^^^^^^
  File "/home/airflow/.local/lib/python3.12/site-packages/airflow/providers/google/common/hooks/base_google.py", line 553, in inner_wrapper
    return func(self, *args, **kwargs)
           ^^^^^^^^^^^^^^^^^^^^^^^^^^^
  File "/home/airflow/.local/lib/python3.12/site-packages/airflow/providers/google/cloud/hooks/bigquery.py", line 530, in create_table
    result = self.get_client(project_id=project_id, location=location).create_table(
             ^^^^^^^^^^^^^^^^^^^^^^^^^^^^^^^^^^^^^^^^^^^^^^^^^^^^^^^^^^^^^^^^^^^^^^^
  File "/home/airflow/.local/lib/python3.12/site-packages/google/cloud/bigquery/client.py", line 797, in create_table
    api_response = self._call_api(
                   ^^^^^^^^^^^^^^^
  File "/home/airflow/.local/lib/python3.12/site-packages/google/cloud/bigquery/client.py", line 831, in _call_api
    return call()
           ^^^^^^
  File "/home/airflow/.local/lib/python3.12/site-packages/google/api_core/retry/retry_unary.py", line 293, in retry_wrapped_func
    return retry_target(
           ^^^^^^^^^^^^^
  File "/home/airflow/.local/lib/python3.12/site-packages/google/api_core/retry/retry_unary.py", line 153, in retry_target
    _retry_error_helper(
  File "/home/airflow/.local/lib/python3.12/site-packages/google/api_core/retry/retry_base.py", line 212, in _retry_error_helper
    raise final_exc from source_exc
  File "/home/airflow/.local/lib/python3.12/site-packages/google/api_core/retry/retry_unary.py", line 144, in retry_target
    result = target()
             ^^^^^^^^
  File "/home/airflow/.local/lib/python3.12/site-packages/google/cloud/_http/__init__.py", line 494, in api_request
    raise exceptions.from_http_response(response)
google.api_core.exceptions.BadRequest: 400 POST https://bigquery.googleapis.com/bigquery/v2/projects/nlpfakenews/datasets/fake_news_detection/tables?prettyPrint=false: Invalid value for type: INT is not a valid value
[2025-04-01T14:52:29.090+0000] {logging_mixin.py:190} INFO - Task instance in failure state
[2025-04-01T14:52:29.094+0000] {logging_mixin.py:190} INFO - Task start:2025-04-01 14:52:26.634934+00:00 end:2025-04-01 14:52:29.089936+00:00 duration:2.455002
[2025-04-01T14:52:29.095+0000] {logging_mixin.py:190} INFO - Task:<Task(BigQueryCreateTableOperator): create_table> dag:<DAG: my_dag_name> dagrun:<DagRun my_dag_name @ 2021-12-30 00:00:00+00:00: scheduled__2021-12-30T00:00:00+00:00, state:running, queued_at: 2025-04-01 14:51:23.779461+00:00. externally triggered: False>
[2025-04-01T14:52:29.096+0000] {logging_mixin.py:190} INFO - Failure caused by 400 POST https://bigquery.googleapis.com/bigquery/v2/projects/nlpfakenews/datasets/fake_news_detection/tables?prettyPrint=false: Invalid value for type: INT is not a valid value
[2025-04-01T14:52:29.096+0000] {taskinstance.py:1226} INFO - Marking task as FAILED. dag_id=my_dag_name, task_id=create_table, run_id=scheduled__2021-12-30T00:00:00+00:00, execution_date=20211230T000000, start_date=20250401T145226, end_date=20250401T145229
[2025-04-01T14:52:29.381+0000] {taskinstance.py:341} INFO - ::group::Post task execution logs
[2025-04-01T14:52:29.388+0000] {standard_task_runner.py:124} ERROR - Failed to execute job 751 for task create_table (400 POST https://bigquery.googleapis.com/bigquery/v2/projects/nlpfakenews/datasets/fake_news_detection/tables?prettyPrint=false: Invalid value for type: INT is not a valid value; 3398)
Traceback (most recent call last):
  File "/home/airflow/.local/lib/python3.12/site-packages/airflow/task/task_runner/standard_task_runner.py", line 117, in _start_by_fork
    ret = args.func(args, dag=self.dag)
          ^^^^^^^^^^^^^^^^^^^^^^^^^^^^^
  File "/home/airflow/.local/lib/python3.12/site-packages/airflow/cli/cli_config.py", line 49, in command
    return func(*args, **kwargs)
           ^^^^^^^^^^^^^^^^^^^^^
  File "/home/airflow/.local/lib/python3.12/site-packages/airflow/utils/cli.py", line 116, in wrapper
    return f(*args, **kwargs)
           ^^^^^^^^^^^^^^^^^^
  File "/home/airflow/.local/lib/python3.12/site-packages/airflow/cli/commands/task_command.py", line 483, in task_run
    task_return_code = _run_task_by_selected_method(args, _dag, ti)
                       ^^^^^^^^^^^^^^^^^^^^^^^^^^^^^^^^^^^^^^^^^^^^
  File "/home/airflow/.local/lib/python3.12/site-packages/airflow/cli/commands/task_command.py", line 256, in _run_task_by_selected_method
    return _run_raw_task(args, ti)
           ^^^^^^^^^^^^^^^^^^^^^^^
  File "/home/airflow/.local/lib/python3.12/site-packages/airflow/cli/commands/task_command.py", line 341, in _run_raw_task
    return ti._run_raw_task(
           ^^^^^^^^^^^^^^^^^
  File "/home/airflow/.local/lib/python3.12/site-packages/airflow/utils/session.py", line 97, in wrapper
    return func(*args, session=session, **kwargs)
           ^^^^^^^^^^^^^^^^^^^^^^^^^^^^^^^^^^^^^^
  File "/home/airflow/.local/lib/python3.12/site-packages/airflow/models/taskinstance.py", line 3006, in _run_raw_task
    return _run_raw_task(
           ^^^^^^^^^^^^^^
  File "/home/airflow/.local/lib/python3.12/site-packages/airflow/models/taskinstance.py", line 274, in _run_raw_task
    TaskInstance._execute_task_with_callbacks(
  File "/home/airflow/.local/lib/python3.12/site-packages/airflow/models/taskinstance.py", line 3161, in _execute_task_with_callbacks
    result = self._execute_task(context, task_orig)
             ^^^^^^^^^^^^^^^^^^^^^^^^^^^^^^^^^^^^^^
  File "/home/airflow/.local/lib/python3.12/site-packages/airflow/models/taskinstance.py", line 3185, in _execute_task
    return _execute_task(self, context, task_orig)
           ^^^^^^^^^^^^^^^^^^^^^^^^^^^^^^^^^^^^^^^
  File "/home/airflow/.local/lib/python3.12/site-packages/airflow/models/taskinstance.py", line 768, in _execute_task
    result = _execute_callable(context=context, **execute_callable_kwargs)
             ^^^^^^^^^^^^^^^^^^^^^^^^^^^^^^^^^^^^^^^^^^^^^^^^^^^^^^^^^^^^^
  File "/home/airflow/.local/lib/python3.12/site-packages/airflow/models/taskinstance.py", line 734, in _execute_callable
    return ExecutionCallableRunner(
           ^^^^^^^^^^^^^^^^^^^^^^^^
  File "/home/airflow/.local/lib/python3.12/site-packages/airflow/utils/operator_helpers.py", line 252, in run
    return self.func(*args, **kwargs)
           ^^^^^^^^^^^^^^^^^^^^^^^^^^
  File "/home/airflow/.local/lib/python3.12/site-packages/airflow/models/baseoperator.py", line 424, in wrapper
    return func(self, *args, **kwargs)
           ^^^^^^^^^^^^^^^^^^^^^^^^^^^
  File "/home/airflow/.local/lib/python3.12/site-packages/airflow/providers/google/cloud/operators/bigquery.py", line 1275, in execute
    self._table = bq_hook.create_table(
                  ^^^^^^^^^^^^^^^^^^^^^
  File "/home/airflow/.local/lib/python3.12/site-packages/airflow/providers/google/common/hooks/base_google.py", line 553, in inner_wrapper
    return func(self, *args, **kwargs)
           ^^^^^^^^^^^^^^^^^^^^^^^^^^^
  File "/home/airflow/.local/lib/python3.12/site-packages/airflow/providers/google/cloud/hooks/bigquery.py", line 530, in create_table
    result = self.get_client(project_id=project_id, location=location).create_table(
             ^^^^^^^^^^^^^^^^^^^^^^^^^^^^^^^^^^^^^^^^^^^^^^^^^^^^^^^^^^^^^^^^^^^^^^^
  File "/home/airflow/.local/lib/python3.12/site-packages/google/cloud/bigquery/client.py", line 797, in create_table
    api_response = self._call_api(
                   ^^^^^^^^^^^^^^^
  File "/home/airflow/.local/lib/python3.12/site-packages/google/cloud/bigquery/client.py", line 831, in _call_api
    return call()
           ^^^^^^
  File "/home/airflow/.local/lib/python3.12/site-packages/google/api_core/retry/retry_unary.py", line 293, in retry_wrapped_func
    return retry_target(
           ^^^^^^^^^^^^^
  File "/home/airflow/.local/lib/python3.12/site-packages/google/api_core/retry/retry_unary.py", line 153, in retry_target
    _retry_error_helper(
  File "/home/airflow/.local/lib/python3.12/site-packages/google/api_core/retry/retry_base.py", line 212, in _retry_error_helper
    raise final_exc from source_exc
  File "/home/airflow/.local/lib/python3.12/site-packages/google/api_core/retry/retry_unary.py", line 144, in retry_target
    result = target()
             ^^^^^^^^
  File "/home/airflow/.local/lib/python3.12/site-packages/google/cloud/_http/__init__.py", line 494, in api_request
    raise exceptions.from_http_response(response)
google.api_core.exceptions.BadRequest: 400 POST https://bigquery.googleapis.com/bigquery/v2/projects/nlpfakenews/datasets/fake_news_detection/tables?prettyPrint=false: Invalid value for type: INT is not a valid value
[2025-04-01T14:52:29.547+0000] {local_task_job_runner.py:266} INFO - Task exited with return code 1
[2025-04-01T14:52:29.662+0000] {taskinstance.py:3901} INFO - 0 downstream tasks scheduled from follow-on schedule check
[2025-04-01T14:52:29.671+0000] {local_task_job_runner.py:245} INFO - ::endgroup::
